Workbook

Sheet Tasks
A1: ID | B1: Fred tracker ID | C1: Workstream | D1: Journey | E1: Task | F1: Owner | G1: Org | H1: Priority | I1: Due | J1: Status | K1: Depends on | L1: Notes / source
A2: A1 | B2: TECH-01 | C2: Planning & documentation | D2: All | E2: Fill updated journey doc columns (policy/technical questions, readiness gaps, Discussion) for J1–J4.1 | F2: RM | G2: Nawi | H2: Critical path | I2: 46315 | J2: In progress | L2: Before Wed 21 Oct sync; cell text drafted
A3: A2 | B3: TECH-03 | C3: Planning & documentation | D3: All | E3: Fix dated vignette timeline (birth date, 6-month visit, travel date) so test data and schedule rules agree | F3: RM | G3: Nawi | H3: Critical path | I3: 46315 | J3: Not started | K3: B1 | L3: Coordinate with RR test data
A4: A3 | B4: TECH-09 | C4: Planning & documentation | D4: All | E4: Full requirements / technical specification document (production-level requirements even where implementation is mock) | F4: RM | G4: Nawi | H4: Critical path | I4: 46318 | J4: Not started | K4: A1 | L4: Carl: document at production level
A5: A4 | B5: TECH-09 | C5: Planning & documentation | D5: All | E5: IG scaffold on WHO repo: BPMN process diagrams, user stories, terminology, test data, links to DVC / VHL / PCF specs | F5: RM / CL | G5: Nawi/WHO | H5: Critical path | I5: 46332 | J5: Not started | K5: A3 | L5: Agreed 16 Oct; also shown as best-practice workflow documentation
A6: A5 | B6: JOINT-01 | C6: Planning & documentation | D6: All | E6: Weekly sync (next: Wed 21 Oct 13:00 Geneva); add AeHIN and Mark to invite | F6: CL / FH | G6: WHO/Google | H6: Critical path | I6: 46316 | J6: In progress
A7: A6 | B7: TECH-03 | C7: Planning & documentation | D7: J1–J3 | E7: Request real vaccine lists from two countries (via AeHIN) so the code-set discrepancy is concrete | F7: CL | G7: WHO | H7: Nice to have | I7: TBC | J7: Not started | L7: Carl suggestion 16 Oct
A8: B1 | B8: TECH-03 | C8: Issuance & test data | D8: J1 | E8: Single-vaccine DVC / IPS example from existing test-bed data; confirm it matches a newborn first-dose story | F8: RR | G8: WHO | H8: Critical path | I8: 46314 | J8: In progress | L8: Hajj / Rexel examples; content embedded in QR, no portal lookup
A9: B2 | B9: TECH-03 | C9: Issuance & test data | D9: J1 | E9: Document QR-generation steps | F9: RR | G9: WHO | H9: Critical path | I9: 46314 | J9: Not started
A10: B3 | B10: TECH-03 | C10: Issuance & test data | D10: J1 | E10: Requirements doc from Hajj / Rexel scenarios (basis for verification API requirements) | F10: RR | G10: WHO | H10: Critical path | I10: 46314 | J10: Not started | L10: Reviewed Monday per Carl
A11: B4 | B11: TECH-03 | C11: Issuance & test data | D11: J1 | E11: Generation tool for test DVCs if existing data does not fit the story | F11: CL | G11: WHO | H11: Critical path | I11: 46318 | J11: Not started | K11: B1
A12: B5 | B12: TECH-03 | C12: Issuance & test data | D12: J1 | E12: Locate and review Roxel wiki documentation | F12: CL | G12: WHO | H12: Nice to have | I12: 46318 | J12: Not started
A13: B6 | B13: TECH-02 | C13: Issuance & test data | D13: J1 | E13: Pre-printed QR cards + optional pre-recorded issuance video | F13: CL / RR | G13: WHO | H13: Critical path | I13: 46319 | J13: Not started | K13: B1 | L13: Issuance is simulated, not live
A14: B7 | B14: TECH-03 | C14: Issuance & test data | D14: J3 | E14: Provision DEV trust-list keys / PKI material for demo devices | F14: CL | G14: WHO | H14: Critical path | I14: 46317 | J14: Not started | L14: https://smart.who.int/trust/endpoints.html
A15: C1 | B15: TECH-04 | C15: Verification library | D15: J3, J4.1 | E15: Pull verifiers repo (last Rexel update) and confirm it runs | F15: RR | G15: WHO | H15: Critical path | I15: 46314 | J15: Not started | L15: gdhcn-validator
A16: C2 | B16: TECH-04 | C16: Verification library | D16: J3, J4.1 | E16: Review API requirements doc; identify gaps for the library | F16: CL / JCT / RM | G16: WHO/Nawi | H16: Critical path | I16: 46315 | J16: Not started | K16: B3
A17: C3 | B17: TECH-04 | C17: Verification library | D17: J3, J4.1 | E17: Transcode Python validator REST API to Kotlin | F17: JCT | G17: WHO | H17: Critical path | I17: 46317 | J17: Not started | K17: C2
A18: C4 | B18: TECH-04 | C18: Verification library | D18: J3, J4.1 | E18: Deliver Kotlin multiplatform QR/HCERT extraction + DVC and VHL-manifest verification library to Nawi for testing | F18: CL | G18: WHO | H18: Critical path | I18: 46318 | J18: Not started | K18: C3 | L18: 'mid next week' per Carl
A19: C5 | B19: TECH-05 | C19: Verification library | D19: J2, J3, J4.1 | E19: QR reader component working cross-platform (Android; web on tablet) | F19: Nawi eng | G19: Nawi | H19: Critical path | I19: 46322 | J19: Not started | L19: Fred: priority
A20: C6 | B20: TECH-06 | C20: Verification library | D20: J3, J4.1 | E20: Integrate verification library into OHS Player (J3 DVC verify; J4.1 manifest verify) with cached keys for offline | F20: Nawi eng | G20: Nawi | H20: Critical path | I20: 46330 | J20: Not started | K20: C4, C5
A21: D1 | B21: TECH-09 | C21: Player configurations | D21: J1–J3 | E21: Terminology: ValueSets country-a-vaccines / country-b-vaccines, deliberately unmapped, one shared vaccine coded differently | F21: Nawi eng | G21: Nawi | H21: Critical path | I21: 46325 | J21: Not started | K21: A2
A22: D2 | B22: TECH-05 | C22: Player configurations | D22: J2 | E22: Community config: household roster, newborn registration, QR decode (no verify), Immunization as unverified (primarySource=false, reportOrigin), referral ServiceRequest to seeded facility | F22: Nawi eng | G22: Nawi | H22: Critical path | I22: 46323 | J22: Not started | K22: C5, D1
A23: D3 | B23: TECH-06 | C23: Player configurations | D23: J3 | E23: EHR config (web on tablet / Android): scan, verify, import with Provenance, PlanDefinition/FHIRPath schedule vs Country B rules, reminder Task/Appointment | F23: Nawi eng | G23: Nawi | H23: Critical path | I23: 46330 | J23: Not started | K23: C6, D1
A24: D4 | B24: TECH-07 | C24: Player configurations | D24: J4.0 | E24: Family config: member profiles (Group/RelatedPerson), pull records, one VHL QR per traveller with passcode | F24: Nawi eng | G24: Nawi | H24: Critical path | I24: 46336 | J24: Not started | K24: E1 | L24: Three VHLs / IPS / QRs: mother, father, baby
A25: D5 | B25: TECH-07 | C25: Player configurations | D25: J4.1 | E25: Viewer config: scan VHL QR, passcode, fetch manifest, verify, display | F25: Nawi eng | G25: Nawi | H25: Critical path | I25: 46336 | J25: Not started | K25: C6, E1
A26: D6 | B26: TECH-03 | C26: Player configurations | D26: All | E26: Seed data and fixed dates for demo devices | F26: Nawi eng | G26: Nawi | H26: Critical path | I26: 46323 | J26: Not started | K26: A2, B1
A27: D7 | B27: TECH-10 | C27: Player configurations | D27: J3, J4.1 | E27: AuditEvent at Info Gateway for verification and VHL fetches | F27: Nawi eng | G27: Nawi | H27: Critical path | I27: 46338 | J27: Not started | K27: D3, D5
A28: D8 | B28: TECH-10 | C28: Player configurations | D28: J4.0 | E28: Consent-to-share captured at VHL generation (Consent / AuditEvent; IHE PCF as reference) | F28: Nawi eng | G28: Nawi | H28: Nice to have | I28: TBC | J28: Not started | K28: D4 | L28: Nice-to-have / commentary per Fred
A29: D9 | B29: TECH-07 | C29: Player configurations | D29: J4.0 | E29: SMS / WhatsApp delivery of records or links | F29: Nawi eng | G29: Nawi | H29: Nice to have | I29: TBC | J29: Not started | K29: D4 | L29: Deferred
A30: E1 | B30: TECH-08 | C30: VHL issuer / host | D30: J4.0, J4.1 | E30: Mock VHL issuer: FHIR server exposing VHL endpoints with the three IPS, signed; hosted on Nawi OHS servers | F30: Nawi eng / JCT | G30: Nawi/WHO | H30: Critical path | I30: 46332 | J30: Not started | K30: B1 | L30: Small mock, not Docker-heavy; requirements still production-level
A31: E2 | B31: TECH-08 | C31: VHL issuer / host | D31: J4.0 | E31: Evaluate OpenFn approach to fetch from FHIR server and package IPS / VHL payloads | F31: RM | G31: Nawi | H31: Nice to have | I31: 46325 | J31: Not started
A32: E3 | B32: TECH-08 | C32: VHL issuer / host | D32: J4.0, J4.1 | E32: ITB VHL issuer prototype (reference / test environment) | F32: CL / WHO | G32: WHO | H32: Critical path | I32: 46325 | J32: Not started | L32: Targeted week of 27 Oct
A33: E4 | B33: TECH-08 | C33: VHL issuer / host | D33: J4.1 | E33: Fallback: pre-packaged VHL QR codes handed to Nawi | F33: CL / RR | G33: WHO | H33: Critical path | I33: TBC | J33: Not started | L33: Used if E1/E3 slip
A34: E5 | B34: TECH-07 | C34: VHL issuer / host | D34: J4.0 | E34: Sync with Jing on prior SHL / portable-record work | F34: RM | G34: Nawi | H34: Critical path | I34: 46316 | J34: Not started
A35: E6 | B35: TECH-08 | C35: VHL issuer / host | D35: J4.0 | E35: Hunt Roxel team VHL demos and open-source tools | F35: CL | G35: WHO | H35: Nice to have | I35: 46318 | J35: Not started
A36: E7 | B36: TECH-10 | C36: VHL issuer / host | D36: J4.0 | E36: Review IHE Privacy Consent on FHIR (PCF) for consent breakout content | F36: RM | G36: Nawi | H36: Nice to have | I36: 46318 | J36: Not started
A37: F1 | B37: TECH-11 | C37: Workshop content | D37: J5 | E37: Nawi content / code-lab plan (partially assembled kits, steps 3, 7, 11; curated final assembly) | F37: RM / FH | G37: Nawi/Google | H37: Critical path | I37: 46340 | J37: Not started | L37: Initial plan already shared
A38: F2 | B38: TECH-11 | C38: Workshop content | D38: J5 | E38: Legacy-system mapping as short tech talks + demos (not a breakout) | F38: FH | G38: Google | H38: Critical path | I38: TBC | J38: Not started
A39: F3 | B39: POL-06 | C39: Workshop content | D39: All | E39: Align partner and country demonstration slots (CSIRO, OpenFn, TH, ID, MY, LA, KH) | F39: GM / DW / AM | G39: WHO | H39: Critical path | I39: 46338 | J39: Not started | L39: Section 4 of doc
A40: F4 | B40: POL-05 | C40: Workshop content | D40: All | E40: Policy-track discussion points: code-set governance, consent (PCF), audit / GDPR-style access, DVC vs ICVP | F40: CL / Mark | G40: WHO | H40: Critical path | I40: 46336 | J40: Not started | K40: A4
...

Sheet Summary
A1: Workshop date (Mon–Tue, confirm) | B1: 46356
A3: By owner
A4: Owner | B4: Total | C4: Not started | D4: In progress | E4: Blocked | F4: Done | G4: Critical path
A5: RM | B5: =COUNTIF(Tasks!$F:$F,"*RM*") -> 12 | C5: =COUNTIFS(Tasks!$F:$F,"*RM*",Tasks!$J:$J,"Not started") -> 11 | D5: =COUNTIFS(Tasks!$F:$F,"*RM*",Tasks!$J:$J,"In progress") -> 1 | E5: =COUNTIFS(Tasks!$F:$F,"*RM*",Tasks!$J:$J,"Blocked") -> 0 | F5: =COUNTIFS(Tasks!$F:$F,"*RM*",Tasks!$J:$J,"Done") -> 0 | G5: =COUNTIFS(Tasks!$F:$F,"*RM*",Tasks!$H:$H,"Critical path") -> 10
A6: RR | B6: =COUNTIF(Tasks!$F:$F,"*RR*") -> 6 | C6: =COUNTIFS(Tasks!$F:$F,"*RR*",Tasks!$J:$J,"Not started") -> 5 | D6: =COUNTIFS(Tasks!$F:$F,"*RR*",Tasks!$J:$J,"In progress") -> 1 | E6: =COUNTIFS(Tasks!$F:$F,"*RR*",Tasks!$J:$J,"Blocked") -> 0 | F6: =COUNTIFS(Tasks!$F:$F,"*RR*",Tasks!$J:$J,"Done") -> 0 | G6: =COUNTIFS(Tasks!$F:$F,"*RR*",Tasks!$H:$H,"Critical path") -> 6
A7: CL | B7: =COUNTIF(Tasks!$F:$F,"*CL*") -> 16 | C7: =COUNTIFS(Tasks!$F:$F,"*CL*",Tasks!$J:$J,"Not started") -> 15 | D7: =COUNTIFS(Tasks!$F:$F,"*CL*",Tasks!$J:$J,"In progress") -> 1 | E7: =COUNTIFS(Tasks!$F:$F,"*CL*",Tasks!$J:$J,"Blocked") -> 0 | F7: =COUNTIFS(Tasks!$F:$F,"*CL*",Tasks!$J:$J,"Done") -> 0 | G7: =COUNTIFS(Tasks!$F:$F,"*CL*",Tasks!$H:$H,"Critical path") -> 13
A8: JCT | B8: =COUNTIF(Tasks!$F:$F,"*JCT*") -> 3 | C8: =COUNTIFS(Tasks!$F:$F,"*JCT*",Tasks!$J:$J,"Not started") -> 3 | D8: =COUNTIFS(Tasks!$F:$F,"*JCT*",Tasks!$J:$J,"In progress") -> 0 | E8: =COUNTIFS(Tasks!$F:$F,"*JCT*",Tasks!$J:$J,"Blocked") -> 0 | F8: =COUNTIFS(Tasks!$F:$F,"*JCT*",Tasks!$J:$J,"Done") -> 0 | G8: =COUNTIFS(Tasks!$F:$F,"*JCT*",Tasks!$H:$H,"Critical path") -> 3
A9: FH | B9: =COUNTIF(Tasks!$F:$F,"*FH*") -> 5 | C9: =COUNTIFS(Tasks!$F:$F,"*FH*",Tasks!$J:$J,"Not started") -> 4 | D9: =COUNTIFS(Tasks!$F:$F,"*FH*",Tasks!$J:$J,"In progress") -> 1 | E9: =COUNTIFS(Tasks!$F:$F,"*FH*",Tasks!$J:$J,"Blocked") -> 0 | F9: =COUNTIFS(Tasks!$F:$F,"*FH*",Tasks!$J:$J,"Done") -> 0 | G9: =COUNTIFS(Tasks!$F:$F,"*FH*",Tasks!$H:$H,"Critical path") -> 5
A10: Nawi eng | B10: =COUNTIF(Tasks!$F:$F,"*Nawi eng*") -> 12 | C10: =COUNTIFS(Tasks!$F:$F,"*Nawi eng*",Tasks!$J:$J,"Not started") -> 12 | D10: =COUNTIFS(Tasks!$F:$F,"*Nawi eng*",Tasks!$J:$J,"In progress") -> 0 | E10: =COUNTIFS(Tasks!$F:$F,"*Nawi eng*",Tasks!$J:$J,"Blocked") -> 0 | F10: =COUNTIFS(Tasks!$F:$F,"*Nawi eng*",Tasks!$J:$J,"Done") -> 0 | G10: =COUNTIFS(Tasks!$F:$F,"*Nawi eng*",Tasks!$H:$H,"Critical path") -> 10
A11: WHO (other) | B11: =COUNTIFS(Tasks!$G:$G,"WHO",Tasks!$F:$F,"GM / DW / AM") -> 1 | C11: =COUNTIFS(Tasks!$G:$G,"WHO",Tasks!$F:$F,"GM / DW / AM",Tasks!$J:$J,"Not started") -> 1 | D11: =COUNTIFS(Tasks!$G:$G,"WHO",Tasks!$F:$F,"GM / DW / AM",Tasks!$J:$J,"In progress") -> 0 | E11: =COUNTIFS(Tasks!$G:$G,"WHO",Tasks!$F:$F,"GM / DW / AM",Tasks!$J:$J,"Blocked") -> 0 | F11: =COUNTIFS(Tasks!$G:$G,"WHO",Tasks!$F:$F,"GM / DW / AM",Tasks!$J:$J,"Done") -> 0 | G11: =COUNTIFS(Tasks!$G:$G,"WHO",Tasks!$F:$F,"GM / DW / AM",Tasks!$H:$H,"Critical path") -> 1
A12: Note: shared tasks (e.g. 'CL / RR') count once under each named owner.
A14: By workstream
A15: Workstream | B15: Total | C15: Done | D15: Open | E15: Critical path open
A16: Planning & documentation | B16: =COUNTIF(Tasks!$C:$C,"Planning & documentation") -> 6 | C16: =COUNTIFS(Tasks!$C:$C,"Planning & documentation",Tasks!$J:$J,"Done") -> 0 | D16: =B16-C16 -> 6 | E16: =COUNTIFS(Tasks!$C:$C,"Planning & documentation",Tasks!$H:$H,"Critical path",Tasks!$J:$J,"<>Done") -> 5
A17: Issuance & test data | B17: =COUNTIF(Tasks!$C:$C,"Issuance & test data") -> 7 | C17: =COUNTIFS(Tasks!$C:$C,"Issuance & test data",Tasks!$J:$J,"Done") -> 0 | D17: =B17-C17 -> 7 | E17: =COUNTIFS(Tasks!$C:$C,"Issuance & test data",Tasks!$H:$H,"Critical path",Tasks!$J:$J,"<>Done") -> 6
A18: Verification library | B18: =COUNTIF(Tasks!$C:$C,"Verification library") -> 6 | C18: =COUNTIFS(Tasks!$C:$C,"Verification library",Tasks!$J:$J,"Done") -> 0 | D18: =B18-C18 -> 6 | E18: =COUNTIFS(Tasks!$C:$C,"Verification library",Tasks!$H:$H,"Critical path",Tasks!$J:$J,"<>Done") -> 6
A19: Player configurations | B19: =COUNTIF(Tasks!$C:$C,"Player configurations") -> 9 | C19: =COUNTIFS(Tasks!$C:$C,"Player configurations",Tasks!$J:$J,"Done") -> 0 | D19: =B19-C19 -> 9 | E19: =COUNTIFS(Tasks!$C:$C,"Player configurations",Tasks!$H:$H,"Critical path",Tasks!$J:$J,"<>Done") -> 7
A20: VHL issuer / host | B20: =COUNTIF(Tasks!$C:$C,"VHL issuer / host") -> 7 | C20: =COUNTIFS(Tasks!$C:$C,"VHL issuer / host",Tasks!$J:$J,"Done") -> 0 | D20: =B20-C20 -> 7 | E20: =COUNTIFS(Tasks!$C:$C,"VHL issuer / host",Tasks!$H:$H,"Critical path",Tasks!$J:$J,"<>Done") -> 4
A21: Workshop content | B21: =COUNTIF(Tasks!$C:$C,"Workshop content") -> 7 | C21: =COUNTIFS(Tasks!$C:$C,"Workshop content",Tasks!$J:$J,"Done") -> 0 | D21: =B21-C21 -> 7 | E21: =COUNTIFS(Tasks!$C:$C,"Workshop content",Tasks!$H:$H,"Critical path",Tasks!$J:$J,"<>Done") -> 7
A23: Due this week / overdue
A24: Open tasks due on or before | B24: 46318 | C24: =COUNTIFS(Tasks!$I:$I,"<="&B24,Tasks!$J:$J,"<>Done") -> 17
A26: Legend
A27: Yellow cells are for you to edit (owner, priority, due, status on Tasks; workshop date and cut-off here).
A28: Owners: RM Roy Munge · RR Ritika Rawlani · CL Carl Leitner · JCT Jose Costa Teixeira · FH Fred Hersch · GM/DW/AM Garrett Mehl / Diana Wijayanti / Alvin Marcelo · Nawi eng = Nawi engineering team.
A29: Due dates: items stated on the 14 and 16 Oct calls are as given; the rest are aligned to the parent task dates in Fred Hersch's master tracker (Fred tracker ID column). Keep that tracker as the master; this sheet is the technical sub-task breakdown.
A30: Summary formulas recalculate as the Tasks sheet changes; add new rows anywhere on Tasks.

Sheet Milestones
A1: Date | B1: Milestone | C1: Owner | D1: Status
A2: 46314 | B2: Single-vaccine DVC/IPS example + QR steps + API requirements doc | C2: RR | D2: In progress
A3: 46315 | B3: Journey doc columns filled; timeline fixed; API requirements reviewed | C3: RM / CL / JCT | D3: In progress
A4: 46316 | B4: Weekly sync — VHL approach confirmed, verification library requirements reviewed | C4: All | D4: Not started
A5: 46318 | B5: Kotlin verification library delivered to Nawi (TECH-04) | C5: CL / JCT | D5: Not started
A6: 46323 | B6: J2 community config reads QR offline and refers (TECH-05) | C6: Nawi | D6: Not started
A7: 46330 | B7: J3 clinic config verifies signatures and calculates schedule (TECH-06) | C7: Nawi | D7: Not started
A8: 46332 | B8: Mock VHL issuer live; IG published on WHO repo (TECH-08, TECH-09) | C8: Nawi / WHO | D8: Not started
A9: 46336 | B9: J4.0 and J4.1 family configs resolve three VHLs (TECH-07) | C9: Nawi | D9: Not started
A10: 46340 | B10: Day 1 code labs packaged (TECH-11) | C10: FH / RM | D10: Not started
A11: 46351 | B11: Full end-to-end rehearsal (TECH-13) | C11: All | D11: Not started
A12: 46356 | B12: Pre-GDHF workshop, Bangkok, 30 Nov to 1 Dec | C12: All | D12: Not started
A13: Milestone dates follow Fred Hersch's master plan (TECH/JOINT IDs); sub-task dates on the Tasks sheet are set to land before their parent.
